Traceback (most recent call last):
  File "C:\Users\sss0031\AppData\Local\miniforge3\envs\opy\lib\site-packages\jupyter_cache\executors\utils.py", line 58, in single_nb_execution
    executenb(
  File "C:\Users\sss0031\AppData\Local\miniforge3\envs\opy\lib\site-packages\nbclient\client.py", line 1314, in execute
    return NotebookClient(nb=nb, resources=resources, km=km, **kwargs).execute()
  File "C:\Users\sss0031\AppData\Local\miniforge3\envs\opy\lib\site-packages\jupyter_core\utils\__init__.py", line 165, in wrapped
    return loop.run_until_complete(inner)
  File "C:\Users\sss0031\AppData\Local\miniforge3\envs\opy\lib\asyncio\base_events.py", line 649, in run_until_complete
    return future.result()
  File "C:\Users\sss0031\AppData\Local\miniforge3\envs\opy\lib\site-packages\nbclient\client.py", line 709, in async_execute
    await self.async_execute_cell(
  File "C:\Users\sss0031\AppData\Local\miniforge3\envs\opy\lib\site-packages\nbclient\client.py", line 1062, in async_execute_cell
    await self._check_raise_for_error(cell, cell_index, exec_reply)
  File "C:\Users\sss0031\AppData\Local\miniforge3\envs\opy\lib\site-packages\nbclient\client.py", line 918, in _check_raise_for_error
    raise CellExecutionError.from_cell_and_msg(cell, exec_reply_content)
nbclient.exceptions.CellExecutionError: An error occurred while executing the following cell:
------------------
import simcentralconnect #AVEVA PROCESS SIMULATION REQUIRED IMPORT TO ENABLE CONNECTION
------------------


[1;31m---------------------------------------------------------------------------[0m
[1;31mModuleNotFoundError[0m                       Traceback (most recent call last)
Cell [1;32mIn[1], line 1[0m
[1;32m----> 1[0m [38;5;28;01mimport[39;00m [38;5;21;01msimcentralconnect[39;00m [38;5;66;03m#AVEVA PROCESS SIMULATION REQUIRED IMPORT TO ENABLE CONNECTION[39;00m

[1;31mModuleNotFoundError[0m: No module named 'simcentralconnect'

