Traceback (most recent call last):
  File "/opt/anaconda3/envs/opyrability/lib/python3.11/site-packages/jupyter_core/utils/__init__.py", line 154, in wrapped
    asyncio.get_running_loop()
RuntimeError: no running event loop

During handling of the above exception, another exception occurred:

Traceback (most recent call last):
  File "/opt/anaconda3/envs/opyrability/lib/python3.11/site-packages/jupyter_cache/executors/utils.py", line 58, in single_nb_execution
    executenb(
  File "/opt/anaconda3/envs/opyrability/lib/python3.11/site-packages/nbclient/client.py", line 1305, in execute
    return NotebookClient(nb=nb, resources=resources, km=km, **kwargs).execute()
           ^^^^^^^^^^^^^^^^^^^^^^^^^^^^^^^^^^^^^^^^^^^^^^^^^^^^^^^^^^^^^^^^^^^^^
  File "/opt/anaconda3/envs/opyrability/lib/python3.11/site-packages/jupyter_core/utils/__init__.py", line 158, in wrapped
    return loop.run_until_complete(inner)
           ^^^^^^^^^^^^^^^^^^^^^^^^^^^^^^
  File "/opt/anaconda3/envs/opyrability/lib/python3.11/asyncio/base_events.py", line 654, in run_until_complete
    return future.result()
           ^^^^^^^^^^^^^^^
  File "/opt/anaconda3/envs/opyrability/lib/python3.11/site-packages/nbclient/client.py", line 705, in async_execute
    await self.async_execute_cell(
  File "/opt/anaconda3/envs/opyrability/lib/python3.11/site-packages/nbclient/client.py", line 1058, in async_execute_cell
    await self._check_raise_for_error(cell, cell_index, exec_reply)
  File "/opt/anaconda3/envs/opyrability/lib/python3.11/site-packages/nbclient/client.py", line 914, in _check_raise_for_error
    raise CellExecutionError.from_cell_and_msg(cell, exec_reply_content)
nbclient.exceptions.CellExecutionError: An error occurred while executing the following cell:
------------------
# remove the following two lines to run on linux
import pythoncom
pythoncom.CoInitialize()

from opyrability import multimodel_rep, OI_eval, AIS2AOS_map
import numpy as np
import matplotlib.pyplot as plt

# Call DWSIM DLLs
import clr
------------------


[31m---------------------------------------------------------------------------[39m
[31mModuleNotFoundError[39m                       Traceback (most recent call last)
[36mCell[39m[36m [39m[32mIn[1][39m[32m, line 2[39m
[32m      1[39m [38;5;66;03m# remove the following two lines to run on linux[39;00m
[32m----> [39m[32m2[39m [38;5;28;01mimport[39;00m[38;5;250m [39m[34;01mpythoncom[39;00m
[32m      3[39m pythoncom.CoInitialize()
[32m      5[39m [38;5;28;01mfrom[39;00m[38;5;250m [39m[34;01mopyrability[39;00m[38;5;250m [39m[38;5;28;01mimport[39;00m multimodel_rep, OI_eval, AIS2AOS_map

[31mModuleNotFoundError[39m: No module named 'pythoncom'

